Workbook

Sheet NOWCAST
A3: Periodo | B3: IPC General | C3: Pronóstico en 11 meses (variación 12 meses) - EEE | D3: Pronóstico Expectativas - Inflación esperada 12 meses IMCE Industria | E3: Pronóstico Last Observation | F3: Pronóstico Historical Mean Forecast | G3: Pronóstico Mean Last 50 Observation | H3: Pronóstico 3% Forecast | I3: Error de Pronóstico en 11 meses (variación 12 meses) - EEE | J3: Error de Pronóstico Expectativas - Inflación esperada 12 meses IMCE Industria | K3: Error de Pronóstico Last Observation | L3: Error de Pronóstico Historical Mean | M3: Error de Pronóstico Mean Last 50 Observation | N3: Error de Pronóstico 3% Forecast | O3: Error Cuadrado de Pronóstico en 11 meses (variación 12 meses) - EEE | P3: Error Cuadrado de Pronóstico Expectativas - Inflación esperada 12 meses IMCE Industria | Q3: Error Cuadrado de Pronóstico Last Observation | R3: Error Cuadrado de Pronóstico Historical Mean | S3: Error Cuadrado de Pronóstico Mean Last 50 Observation | T3: Error Cuadrado de Pronóstico 3% Forecast
A4: 36495 | B4: 2.3202845
A5: 36526 | B5: 2.8316204
A6: 36557 | B6: 3.3276026
A7: 36586 | B7: 3.4272736
A8: 36617 | B8: 3.5302095
A9: 36647 | B9: 3.6357527
A10: 36678 | B10: 3.7285308
A11: 36708 | B11: 3.8046349
A12: 36739 | B12: 3.8629044
A13: 36770 | B13: 4.257691
A14: 36800 | B14: 4.5211704
A15: 36831 | B15: 4.6791907
A16: 36861 | B16: 4.5198961
A17: 36892 | B17: 4.6940508 | C17: 3.7
A18: 36923 | B18: 3.7911115
A19: 36951 | B19: 3.5327633
A20: 36982 | B20: 3.5246543
A21: 37012 | B21: 3.7467351
A22: 37043 | B22: 3.5612914
A23: 37073 | B23: 3.2148764
A24: 37104 | B24: 3.7731704
A25: 37135 | B25: 3.9018127 | C25: 3.6
A26: 37165 | B26: 3.4089152 | C26: 3.8
A27: 37196 | B27: 3.0589446 | C27: 3.9
A28: 37226 | B28: 2.6336219 | C28: 3.5
A29: 37257 | B29: 2.210211 | C29: 3.2
A30: 37288 | B30: 2.5296612 | C30: 3.1
A31: 37316 | B31: 2.5768235 | C31: 3
A32: 37347 | B32: 2.4838623 | C32: 3.1
A33: 37377 | B33: 2.1323921 | C33: 3
A34: 37408 | B34: 1.9484491 | C34: 2.8
A35: 37438 | B35: 2.6000146 | C35: 2.8
A36: 37469 | B36: 2.1761917 | C36: 2.6
... A68: 38443 | B68: 2.9504499 | C68: 2.8
A69: 38473 | B69: 2.6835984 | C69: 2.9 | D69: 3
A70: 38504 | B70: 2.6601726 | C70: 3 | D70: 3
A71: 38534 | B71: 3.0547868 | C71: 2.9 | D71: 3
A72: 38565 | B72: 2.9634009 | C72: 3 | D72: 3.3
A73: 38596 | B73: 3.9622247 | C73: 3.2 | D73: 3.5
...

Sheet PRÓNOSTICO
A3: Periodo | B3: IPC General | C3: Pronóstico en 11 meses (variación 12 meses) - EEE | D3: Pronóstico Expectativas - Inflación esperada 12 meses IMCE Industria | E3: Pronóstico Last Observation | F3: Pronóstico Historical Mean Forecast | G3: Pronóstico Mean Last 50 Observation | H3: Pronóstico 3% Forecast | I3: Error de Pronóstico en 11 meses (variación 12 meses) - EEE | J3: Error de Pronóstico Expectativas - Inflación esperada 12 meses IMCE Industria | K3: Error de Pronóstico Last Observation | L3: Error de Pronóstico Historical Mean | M3: Error de Pronóstico Mean Last 50 Observation | N3: Error de Pronóstico 3% Forecast | O3: Error Cuadrado de Pronóstico en 11 meses (variación 12 meses) - EEE | P3: Error Cuadrado de Pronóstico Expectativas - Inflación esperada 12 meses IMCE Industria | Q3: Error Cuadrado de Pronóstico Last Observation | R3: Error Cuadrado de Pronóstico Historical Mean | S3: Error Cuadrado de Pronóstico Mean Last 50 Observation | T3: Error Cuadrado de Pronóstico 3% Forecast
A4: 36495 | B4: 2.3202845
A5: 36526 | B5: 2.8316204
A6: 36557 | B6: 3.3276026
A7: 36586 | B7: 3.4272736
A8: 36617 | B8: 3.5302095
A9: 36647 | B9: 3.6357527
A10: 36678 | B10: 3.7285308
A11: 36708 | B11: 3.8046349
A12: 36739 | B12: 3.8629044
A13: 36770 | B13: 4.257691
A14: 36800 | B14: 4.5211704
A15: 36831 | B15: 4.6791907
... A17: 36892 | B17: 4.6940508
A18: 36923 | B18: 3.7911115 | C18: 3.7
A19: 36951 | B19: 3.5327633
A20: 36982 | B20: 3.5246543
A21: 37012 | B21: 3.7467351
A22: 37043 | B22: 3.5612914
A23: 37073 | B23: 3.2148764
A24: 37104 | B24: 3.7731704
A25: 37135 | B25: 3.9018127
A26: 37165 | B26: 3.4089152 | C26: 3.6
A27: 37196 | B27: 3.0589446 | C27: 3.8
A28: 37226 | B28: 2.6336219 | C28: 3.9
A29: 37257 | B29: 2.210211 | C29: 3.5
A30: 37288 | B30: 2.5296612 | C30: 3.2
A31: 37316 | B31: 2.5768235 | C31: 3.1
A32: 37347 | B32: 2.4838623 | C32: 3
A33: 37377 | B33: 2.1323921 | C33: 3.1
A34: 37408 | B34: 1.9484491 | C34: 3
A35: 37438 | B35: 2.6000146 | C35: 2.8
A36: 37469 | B36: 2.1761917 | C36: 2.8
A37: 37500 | B37: 2.2926395 | C37: 2.6
... A69: 38473 | B69: 2.6835984 | C69: 2.8
A70: 38504 | B70: 2.6601726 | C70: 2.9 | D70: 3
A71: 38534 | B71: 3.0547868 | C71: 3 | D71: 3
A72: 38565 | B72: 2.9634009 | C72: 2.9 | D72: 3
A73: 38596 | B73: 3.9622247 | C73: 3 | D73: 3.3
A74: 38626 | B74: 4.1531871 | C74: 3.2 | D74: 3.5
...

Sheet ANÁLISIS
A2: PREGUNTA | E2: RESPUESTA
A12: REMC PROYECTO ACTUAL
A13: RECM EEE | B13: RECM IMCE
A14: 2.155 | B14: 1.209
A18: REMC PROYECTO ANTERIOR
A19: RECM EEE | B19: RECM IMCE
A20: 2.16 | B20: 1.21

Sheet MODELO AR(2)
A3: Periodo | B3: IPC General | C3: Pronóstico en 11 meses (variación 12 meses) - EEE | D3: Pronóstico Expectativas - Inflación esperada 12 meses IMCE Industria | E3: Rezago 1 | F3: Rezago 2 | G3: AR(2) | H3: Y(-2) | I3: Y(-1) | J3: Constante | K3: Error | L3: Error al cuadrado
A4: 36495 | B4: 2.3202845
A5: 36526 | B5: 2.8316204 | E5: =B4 -> 2.3202845
A6: 36557 | B6: 3.3276026 | E6: =B5 -> 2.8316204 | F6: =B4 -> 2.3202845
A7: 36586 | B7: 3.4272736 | E7: =B6 -> 3.3276026 | F7: =B5 -> 2.8316204
A8: 36617 | B8: 3.5302095 | E8: =B7 -> 3.4272736 | F8: =B6 -> 3.3276026
A9: 36647 | B9: 3.6357527 | E9: =B8 -> 3.5302095 | F9: =B7 -> 3.4272736
A10: 36678 | B10: 3.7285308 | E10: =B9 -> 3.6357527 | F10: =B8 -> 3.5302095
A11: 36708 | B11: 3.8046349 | E11: =B10 -> 3.7285308 | F11: =B9 -> 3.6357527
A12: 36739 | B12: 3.8629044 | E12: =B11 -> 3.8046349 | F12: =B10 -> 3.7285308
A13: 36770 | B13: 4.257691 | E13: =B12 -> 3.8629044 | F13: =B11 -> 3.8046349
A14: 36800 | B14: 4.5211704 | E14: =B13 -> 4.257691 | F14: =B12 -> 3.8629044
A15: 36831 | B15: 4.6791907 | E15: =B14 -> 4.5211704 | F15: =B13 -> 4.257691
A16: 36861 | B16: 4.5198961 | E16: =B15 -> 4.6791907 | F16: =B14 -> 4.5211704
A17: 36892 | B17: 4.6940508 | C17: 3.7 | E17: =B16 -> 4.5198961 | F17: =B15 -> 4.6791907
A18: 36923 | B18: 3.7911115 | E18: =B17 -> 4.6940508 | F18: =B16 -> 4.5198961
A19: 36951 | B19: 3.5327633 | E19: =B18 -> 3.7911115 | F19: =B17 -> 4.6940508
A20: 36982 | B20: 3.5246543 | E20: =B19 -> 3.5327633 | F20: =B18 -> 3.7911115
A21: 37012 | B21: 3.7467351 | E21: =B20 -> 3.5246543 | F21: =B19 -> 3.5327633
A22: 37043 | B22: 3.5612914 | E22: =B21 -> 3.7467351 | F22: =B20 -> 3.5246543
A23: 37073 | B23: 3.2148764 | E23: =B22 -> 3.5612914 | F23: =B21 -> 3.7467351
A24: 37104 | B24: 3.7731704 | E24: =B23 -> 3.2148764 | F24: =B22 -> 3.5612914
A25: 37135 | B25: 3.9018127 | C25: 3.6 | E25: =B24 -> 3.7731704 | F25: =B23 -> 3.2148764
A26: 37165 | B26: 3.4089152 | C26: 3.8 | E26: =B25 -> 3.9018127 | F26: =B24 -> 3.7731704
A27: 37196 | B27: 3.0589446 | C27: 3.9 | E27: =B26 -> 3.4089152 | F27: =B25 -> 3.9018127
A28: 37226 | B28: 2.6336219 | C28: 3.5 | E28: =B27 -> 3.0589446 | F28: =B26 -> 3.4089152
A29: 37257 | B29: 2.210211 | C29: 3.2 | E29: =B28 -> 2.6336219 | F29: =B27 -> 3.0589446
A30: 37288 | B30: 2.5296612 | C30: 3.1 | E30: =B29 -> 2.210211 | F30: =B28 -> 2.6336219
A31: 37316 | B31: 2.5768235 | C31: 3 | E31: =B30 -> 2.5296612 | F31: =B29 -> 2.210211
A32: 37347 | B32: 2.4838623 | C32: 3.1 | E32: =B31 -> 2.5768235 | F32: =B30 -> 2.5296612
A33: 37377 | B33: 2.1323921 | C33: 3 | E33: =B32 -> 2.4838623 | F33: =B31 -> 2.5768235
A34: 37408 | B34: 1.9484491 | C34: 2.8 | E34: =B33 -> 2.1323921 | F34: =B32 -> 2.4838623
A35: 37438 | B35: 2.6000146 | C35: 2.8 | E35: =B34 -> 1.9484491 | F35: =B33 -> 2.1323921
A36: 37469 | B36: 2.1761917 | C36: 2.6 | E36: =B35 -> 2.6000146 | F36: =B34 -> 1.9484491
... A68: 38443 | B68: 2.9504499 | C68: 2.8 | E68: =B67 -> 2.4038657 | F68: =B66 -> 2.1815861
A69: 38473 | B69: 2.6835984 | C69: 2.9 | D69: 3 | E69: =B68 -> 2.9504499 | F69: =B67 -> 2.4038657
A70: 38504 | B70: 2.6601726 | C70: 3 | D70: 3 | E70: =B69 -> 2.6835984 | F70: =B68 -> 2.9504499
A71: 38534 | B71: 3.0547868 | C71: 2.9 | D71: 3 | E71: =B70 -> 2.6601726 | F71: =B69 -> 2.6835984
A72: 38565 | B72: 2.9634009 | C72: 3 | D72: 3.3 | E72: =B71 -> 3.0547868 | F72: =B70 -> 2.6601726
A73: 38596 | B73: 3.9622247 | C73: 3.2 | D73: 3.5 | E73: =B72 -> 2.9634009 | F73: =B71 -> 3.0547868
...

Sheet PRONOSTICAR CON MODELO AR(2)
A3: Periodo | B3: 1.IPC General | C3: 1.En 11 meses (variación 12 meses) | D3: 1.Expectativas - Inflación esperada 12 meses IMCE Industria | E3: IPC (-1) | F3: IPC (-2)
A4: 36495 | B4: 2.3202845
A5: 36526 | B5: 2.8316204 | E5: =B4 -> 2.3202845
A6: 36557 | B6: 3.3276026 | E6: =B5 -> 2.8316204 | F6: =E5 -> 2.3202845
A7: 36586 | B7: 3.4272736 | E7: =B6 -> 3.3276026 | F7: =E6 -> 2.8316204
A8: 36617 | B8: 3.5302095 | E8: =B7 -> 3.4272736 | F8: =E7 -> 3.3276026
A9: 36647 | B9: 3.6357527 | E9: =B8 -> 3.5302095 | F9: =E8 -> 3.4272736
A10: 36678 | B10: 3.7285308 | E10: =B9 -> 3.6357527 | F10: =E9 -> 3.5302095
A11: 36708 | B11: 3.8046349 | E11: =B10 -> 3.7285308 | F11: =E10 -> 3.6357527
A12: 36739 | B12: 3.8629044 | E12: =B11 -> 3.8046349 | F12: =E11 -> 3.7285308
A13: 36770 | B13: 4.257691 | E13: =B12 -> 3.8629044 | F13: =E12 -> 3.8046349
A14: 36800 | B14: 4.5211704 | E14: =B13 -> 4.257691 | F14: =E13 -> 3.8629044
A15: 36831 | B15: 4.6791907 | E15: =B14 -> 4.5211704 | F15: =E14 -> 4.257691
A16: 36861 | B16: 4.5198961 | E16: =B15 -> 4.6791907 | F16: =E15 -> 4.5211704
A17: 36892 | B17: 4.6940508 | C17: 3.7 | E17: =B16 -> 4.5198961 | F17: =E16 -> 4.6791907
A18: 36923 | B18: 3.7911115 | E18: =B17 -> 4.6940508 | F18: =E17 -> 4.5198961
A19: 36951 | B19: 3.5327633 | E19: =B18 -> 3.7911115 | F19: =E18 -> 4.6940508
A20: 36982 | B20: 3.5246543 | E20: =B19 -> 3.5327633 | F20: =E19 -> 3.7911115
A21: 37012 | B21: 3.7467351 | E21: =B20 -> 3.5246543 | F21: =E20 -> 3.5327633
A22: 37043 | B22: 3.5612914 | E22: =B21 -> 3.7467351 | F22: =E21 -> 3.5246543
A23: 37073 | B23: 3.2148764 | E23: =B22 -> 3.5612914 | F23: =E22 -> 3.7467351
A24: 37104 | B24: 3.7731704 | E24: =B23 -> 3.2148764 | F24: =E23 -> 3.5612914
A25: 37135 | B25: 3.9018127 | C25: 3.6 | E25: =B24 -> 3.7731704 | F25: =E24 -> 3.2148764
A26: 37165 | B26: 3.4089152 | C26: 3.8 | E26: =B25 -> 3.9018127 | F26: =E25 -> 3.7731704
A27: 37196 | B27: 3.0589446 | C27: 3.9 | E27: =B26 -> 3.4089152 | F27: =E26 -> 3.9018127
A28: 37226 | B28: 2.6336219 | C28: 3.5 | E28: =B27 -> 3.0589446 | F28: =E27 -> 3.4089152
A29: 37257 | B29: 2.210211 | C29: 3.2 | E29: =B28 -> 2.6336219 | F29: =E28 -> 3.0589446
A30: 37288 | B30: 2.5296612 | C30: 3.1 | E30: =B29 -> 2.210211 | F30: =E29 -> 2.6336219
A31: 37316 | B31: 2.5768235 | C31: 3 | E31: =B30 -> 2.5296612 | F31: =E30 -> 2.210211
A32: 37347 | B32: 2.4838623 | C32: 3.1 | E32: =B31 -> 2.5768235 | F32: =E31 -> 2.5296612
A33: 37377 | B33: 2.1323921 | C33: 3 | E33: =B32 -> 2.4838623 | F33: =E32 -> 2.5768235
A34: 37408 | B34: 1.9484491 | C34: 2.8 | E34: =B33 -> 2.1323921 | F34: =E33 -> 2.4838623
A35: 37438 | B35: 2.6000146 | C35: 2.8 | E35: =B34 -> 1.9484491 | F35: =E34 -> 2.1323921
A36: 37469 | B36: 2.1761917 | C36: 2.6 | E36: =B35 -> 2.6000146 | F36: =E35 -> 1.9484491
... A68: 38443 | B68: 2.9504499 | C68: 2.8 | E68: =B67 -> 2.4038657 | F68: =E67 -> 2.1815861
A69: 38473 | B69: 2.6835984 | C69: 2.9 | D69: 3 | E69: =B68 -> 2.9504499 | F69: =E68 -> 2.4038657
A70: 38504 | B70: 2.6601726 | C70: 3 | D70: 3 | E70: =B69 -> 2.6835984 | F70: =E69 -> 2.9504499
A71: 38534 | B71: 3.0547868 | C71: 2.9 | D71: 3 | E71: =B70 -> 2.6601726 | F71: =E70 -> 2.6835984
A72: 38565 | B72: 2.9634009 | C72: 3 | D72: 3.3 | E72: =B71 -> 3.0547868 | F72: =E71 -> 2.6601726
A73: 38596 | B73: 3.9622247 | C73: 3.2 | D73: 3.5 | E73: =B72 -> 2.9634009 | F73: =E72 -> 3.0547868
...
